Workbook

Sheet Audit Form
A1: Evaluator
A2: INQ/Case#
A3: Eval Date
A4: Agent
A5: Supervisor
A6: Call Reason
A7: Caller Type
A8: Quality | G8: AHT
A9: Categoy | B9: Attributes | D9: Remarks | E9: SCORE | G9: Attributes | H9: Remarks
A10: Greeting | B10: a. | C10: Agent did not provide their name/department | D10: Pass | E10: 1 | G10: Speed of Answer | H10: Pass
B11: b. | C11: Agent did not verify whom they are speaking to | D11: Pass
A12: Obtaining and documenting Information | B12: a. | C12: Agent did not obtain the name of the caller | D12: Pass | E12: 2
B13: b. | C13: Agent did not obtain Caller's Location, if not member (e.g., MDO, LTC, Hospice). | D13: Pass
B14: c. | C14: Agent did not obtain Caller's callback number. | D14: Pass
B15: d. | C15: Agent did not select the correct caller type OR correct the caller type when it is discovered tom be incorrect | D15: Pass
A16: Member Authentication | B16: a. | C16: Agent did not ask for a third identifier if member ID is not available | D16: Pass | E16: 7 | G16: Unnecessary Caller Validation | H16: Pass
B17: b. | C17: Agent did not obtain member's first and last name | D17: Pass | G17: Irrelevant probing | H17: Pass
B18: c. | C18: Agent did not obtain member's dob | D18: Pass | G18: Repetition of Queries | H18: Pass
B19: d. | C19: Member PHI was inappropriately provided to third party caller | D19: Pass
B20: e. | C20: Agent did not utilize scripting for auto-pop information | D20: Pass
A21: MDO Authentication | B21: a. | C21: Agent did not obtain provider's last name | D21: Pass | E21: 7
B22: b. | C22: Agent did not obtain provider's NPI | D22: Pass
B23: c. | C23: Agent did not authenticate partial address (e.g., street name, street number, city, state) | D23: Pass
B24: d. | C24: Agent did not authenticate office phone number | D24: Pass
B25: e. | C25: Agent did not authenticate office fax number | D25: Pass
B26: f. | C26: Agent did not authenticate the provider information | D26: Pass
B27: g. | C27: Agent did not utilize scripting for auto-pop information | D27: Pass
A28: Pharmacy Authentication | B28: a. | C28: Agent did not obtain pharmacy name | D28: Pass | E28: 7
B29: b. | C29: Agent did not obtain pharmacy NPI or NABP number | D29: Pass
B30: c. | C30: Agent did not ask if caller is from a "dispensing pharmacy" | D30: Pass
B31: d. | C31: Agent did not utilize scripting for auto-pop information | D31: Pass
A32: Authentication Requirement for Client and Internal Callers | B32: a. | C32: Agent did not follow member authentication protocol when accessing the member's account is required | D32: Pass | E32: 6
B33: b. | C33: Agent did not change the caller type to provider or pharmacy as needed and follow the applicable authentication process per caller type | D33: Pass
A34: Transition Question | B34: a. | C34: Agent did not ask the transition question if case populate in member case history | D34: Pass | E34: 1
B35: b. | C35: Agent did not ask the transition question if case populate in member case history if case do not populate in member case history | D35: Pass
B36: c. | C36: Agent did not confirm the caller's needs that was already stated | D36: Pass
A37: First Call Resolution | B37: a. | C37: Agent did not select the correct member account Note: If the member has multiple accounts | D37: Pass | E37: 6 | G37: Issue Identification | H37: Pass
B38: b. | C38: Agent failed to recognize that the account is handled by a dedicated team, did not transfer the call appropriately | D38: Pass | G38: Search Time on Systems | H38: Pass
B39: c. | C39: Agent did not leverage the Identify Provider and Drug and/or Pharmacy from Member Claims to identify the provider, target drug, and pharmacy. | D39: Pass
B40: d. | C40: Agent did not pull up the case history and provide the correct status of case for the target drug | D40: Pass
...

Sheet Nesting 
A1: Status | B1: Nesting
A3: Average of QA Score | B3: Column Labels | F3: Count of Case/INQ | G3: Column Labels
A4: Row Labels | B4: Class 11.1 | C4: Class 11.2 | D4: Grand Total | F4: Row Labels | G4: Jan Week 1 | H4: Jan Week 2 | I4: Grand Total
A5: Jan Week 1 | B5: 0.95636364 | C5: 0.952 | D5: 0.95384615 | F5: Nesting | G5: 26 | H5: 30 | I5: 56
A6: Jan Week 2 | B6: 0.97 | C6: 0.96607143 | D6: 0.96633333 | F6: Class 11.1 | G6: 11 | H6: 2 | I6: 13
A7: Grand Total | B7: 0.95846154 | C7: 0.96116279 | D7: 0.96053571 | F7: Class 11.2 | G7: 15 | H7: 28 | I7: 43
F8: Grand Total | G8: 26 | H8: 30 | I8: 56

Sheet RAW
A1: Month | B1: Status | C1: Class | D1: Week | E1: Date | F1: Agent | G1: Supervisor | H1: Site | I1: Auditor | J1: Caller Type | K1: Call Reason | L1: Case/INQ | M1: QA Score | N1: Agent did not provide their name/department. | O1: Agent did not verify whom they are speaking to. | P1: Agent did not obtain the name of the caller. | Q1: Agent did not obtain Caller's Location, if not member (e.g., MDO, LTC, Hospice). | R1: Agent did not obtain Caller's callback number. | S1: Agent did not select the correct caller type OR correct the caller type when it is discovered tom be incorrect. | T1: Agent did not ask for a third identifier if member ID is not available | U1: Agent did not obtain member's first and last name. | V1: Agent did not obtain member's dob. | W1: Member PHI was inappropriately provided to third party caller. | X1: Agent did not utilize scripting for auto-pop information. | Y1: Agent did not obtain provider's last name. | Z1: Agent did not obtain provider's NPI. | AA1: Agent did not authenticate partial address (e.g., street name, street number, city, state). | AB1: Agent did not authenticate office phone number. | AC1: Agent did not authenticate office fax number. | AD1: Agent did not authenticate the provider information. | AE1: Agent did not utilize scripting for auto-pop information. | AF1: Agent did not obtain pharmacy name. | AG1: Agent did not obtain pharmacy NPI or NABP number. | AH1: Agent did not ask if caller is from a "dispensing pharmacy". | AI1: Agent did not utilize scripting for auto-pop information. | AJ1: Agent did not follow member authentication protocol when accessing the member's account is required. | AK1: Agent did not change the caller type to provider or pharmacy as needed and follow the applicable authentication process per caller type. | AL1: Agent did not ask the transition question if case populate in member case history. | AM1: Agent did not ask the transition question if case populate in member case history if case do not populate in member case history. | AN1: Agent did not confirm the caller's needs that was already stated. | AO1: Agent did not select the correct member account Note: If the member has multiple accounts. | AP1: Agent failed to recognize that the account is handled by a dedicated team, did not transfer the call appropriately. | AQ1: Agent did not leverage the Identify Provider and Drug and/or Pharmacy from Member Claims to identify the provider, target drug, and pharmacy. | AR1: Agent did not pull up the case history and provide the correct status of case for the target drug | AS1: New PA request- The agent did not educate the caller on the availability of an ePA once determined that a PA is required. | AT1: Denied Status Checks - The agent did not inform the caller of the appeals information from the denial correspondence as well as client-specific appeals process information. | AU1: Approved Status Checks - The agent did not inform the caller of the approval duration. | AV1: The agent did not troubleshoot the authorization to get a paid claim. | AW1: Pending Status Checks - The agent did not inform the caller Quoted TAT, status of the pending case, and document any additional information when provided. | AX1: The agent did not correctly update the urgency on a pending case, if requested. | AY1: Miscellaneous - The agent did not resend correspondence(s) when requested. | AZ1: The agent did not assist the caller by providing formulary alternatives, via Formulary Lookup, the trial claim, denial correspondence, etc. when appropriate. | BA1: Agent did not run test claims when appropriate. | BB1: Agent did not provide correct internal/external contact numbers. | BC1: Agent did not offer to create a key code for epa when caller requested fax form to be sent. | BD1: Agent did not accurately send approval/denial correspondence to MDO, when requested. | BE1: Agent did not provide how the PA process works. | BF1: Agent did not provide accurate case turnaround time per the plan time. | BG1: Agent did not provide new/correct member ID, if provided incorrectly. | BH1: Agent did not select the most appropriate dropdown options as a starting point to document the actions taken during the call. | BI1: Agent did not revise the guided verbiage to show what was advise, pertinent action steps done that is not mentioned in the guided verbiage ( i.e. reason for transfer, reason for force pending the case, additional T/F medication, what medication was referenced. | BJ1: False documentation | BK1: Agent did not validate the correct drug product, drug formulation, direction for use, dispensed quantity and days supply. | BL1: Agent should not cancel the phone request when the drug product and formulation has been validated; Agent did not continue with the PA phone request when the call drops after drug product and formulation have been entered. | BM1: Agent did not ensure brand versus generic request; did not correct the error and reenter the drug product. | BN1: Agent did not enter quantity and days supply exactly as the caller's intent. | BO1: Agent did not evaluate the reject in action step. | BP1: Agent did not use retry trial claim to adjust the dispensed quantity and days supply in proportion to 30 days to drive the appropriate rejects. | BQ1: Agent did not enter case detail according to the caller's request (e.g. selecting cost reduction). | BR1: Agent did not turn INQ call to PA when appropriate. | BS1: Merge Decision - Agent did not evaluate and compare the information from the original pending case to the current case when presented with final case duplicates for merging. | BT1: Agent did not follow the system guided "WALKME" instruction at the Enhanced Duplicate Screen. | BU1: Agent did not complete the Multiple PA type selections (when presented appropriately). | BV1: Proceed with the Guideline Decision - New PA requests (e.g., drugs that have not previously been reviewed), must always proceed to the Guideline screen, unless cancellation is warranted. A subsequent commercial case with new information must always proceed to review to evaluate for approval at the Guidelines screen. | BW1: Retry Trial Claim - Agent did not use the retry trial claim feature to adjust the dispensed quantity and days supply in proportion to 30 days to drive the appropriate rejects. | BX1: Agent did not change the day supply to 30 days without also recalculating the quantity to 30 days. | BY1: Cancellation Decision - Agent did not use the retry trial claim feature at the guideline screen first before selecting cancel case. | BZ1: Agent changed the intent of the initial trial claim | CA1: Agent did not select the correct cancel reason code. | CB1: A subsequent Medicare case with a denial on file within the appeal window must be evaluated for Forwarding to Appeals. | CC1: Agent did not ask ALL External questions and responses verbatim. | CD1: Agent did not ask the diagnosis question(s); Agent did not make the correct selection(s) based on the caller's response. | CE1: Agent did not answer initial vs reauth questions correctly. | CF1: Did not ask the CG QL question. | CG1: Did not update the DQ and DS on the case according to the caller's response to the QL question. | CH1: Agent did not document additional information in the additional notes textbox when prompted. | CI1: Agent did not offer to create ePA keycode when CG question require submission of chartnotes. | CJ1: Agent did not evaluate and compare the information from the original pending case to the current case when presented with final/second case duplicates for merging. | CK1: Agent did not follow the system guided "WALKME" instruction at the Enhanced Duplicate Screen. | CL1: The agent did not ensure caller satisfaction by asking if additional assistance is needed. | CM1: The agent did not offers/Mention the survey. | CN1: The agent did not the brand the call and thank the caller. | CO1: Agent did not requests permission from the caller before placing them on hold. | CP1: Agent did not use the mute button when placing the caller on silent hold. | CQ1: Agent did not thank the caller for holding upon returning to the caller. | CR1: Agent placed the caller on hold at the start of the call. | CS1: Agent did not return to the caller from hold after the initial 2mins | CT1: Exceeded Limit of five seconds before the greeting of the call. | CU1: Exceeded Limit of twenty seconds of unannounced silence. | CV1: Exceeded Limit of fifty seconds of announced silence. | CW1: Explain the reason/need to transfer the caller. | CX1: Gain permission from the caller to transfer. | CY1: For internal transfers, agent did not provide the name and number (if available) of the department the caller is being transferred to, and for external Provide the name and number of the department caller is being transferred to. | CZ1: Agent did not warm and cold transfer according to current policy. | DA1: The agent will did not speak clearly without mumbling, using jargon, or slang. | DB1: The agent did not adapt to the caller’s needs through the pace of their speech and the volume of their voice, as appropriate. | DC1: The agent did not avoid using terms of endearment when addressing the caller (e.g., honey, dear). | DD1: The agent did not use appropriate and professional language. | DE1: Agent did not respond with appropriate phrases to ensure the caller they are actively listening and understanding the caller’s statement/question. | DF1: Agent did not resolve all the caller’s needs to ensure the caller does not call back again. (Demonstrate ownership of the repeat caller issue by resolving all questions, issues, and/or concerns on the call); Agent created a homework for the caller. | DG1: Agent did not verify case(s) were reviewed properly. | DH1: Agent did not educate the caller on clinical criteria not met per clinical guidelines based on denial reason. | DI1: Agent did not utilize available resources to research the member’s concerns (i.e. Corr letter, Case Notes, Plan Contacts, Claim History, FLU/INET). | DJ1: The agent will appropriately use the caller’s name at least once during the call outside of caller name verification. | DK1: The agent will address the caller using their last name and/or appropriate name/title anytime the name is provided by the caller. | DL1: The first name may only be used to address clinician, tech, nurse, etc. unless the caller requests the first name be used. | DM1: It is not required to address internal callers by name. | DN1: The agent uses a tone that is pleasant/helpful (PIR). | DO1: The agent uses courtesy words/phrases (PIR). | DP1: The agent allows the caller to speak without blatant interruptions. | DQ1: The agent will concede/apologize if they interrupt the caller, accidentally. | DR1: Agent did not avoid blaming or speaking negatively of OptumRx or company partners. | DS1: Agent did not promote confidence in the company’s processes when speaking to the caller. | DT1: If systems are down or latent, the agent did not advise the caller the “system is updating”. | DU1: Agent spoke negatively of company systems or place blame on systems. | DV1: Agent did not keep the interaction/conversation of the call on track and avoids using distractive fillers. | DW1: Agent did not answer the caller’s questions to build rapport without getting off track. | DX1: Incorrect Case Priority. | DY1: Invalid cancellation - Agent did not work and cancel cases in adherence to compliance requirements. | DZ1: Case Worked for the Incorrect Member - Agent did not work each case with the correct member account as requested by the caller. | EA1: Agent did not maintain professionalism throughout the entire interaction with the caller. Agent used unprofessional or profane language.
A2: =VLOOKUP(E2,'Validation List'!F1:G396,2,FALSE) -> January | B2: =INDEX('NEW HIRE ROSTER'!$G:$G,MATCH(RAW!F2,'NEW HIRE ROSTER'!$A:$A,0)) -> RAMP | C2: =INDEX('NEW HIRE ROSTER'!$F:$F,MATCH(RAW!F2,'NEW HIRE ROSTER'!$A:$A,0)) -> Class 9.1 | D2: =INDEX('Validation List'!$H:$H,MATCH(RAW!E2,'Validation List'!$F:$F,0)) -> Jan Week 1 | E2: 45660 | F2: Abantao,Julius Queno | G2: =VLOOKUP(F2,ML!C2:D588,2,FALSE) -> John Earl Melitado Lagare | H2: =VLOOKUP(F2,ML!C2:E588,3,FALSE) -> QC | I2: Gatchalian,Ernie Marie Caburian | J2: Provider | K2: New PA Initiation | L2: INQ-E860611 | M2: 0.97 | N2: 0 | O2: 0 | P2: 0 | Q2: 0 | R2: 0 | S2: 0 | T2: 0 | U2: 0 | V2: 0 | W2: 0 | X2: 0 | Y2: 0 | Z2: 0 | AA2: 0 | AB2: 0 | AC2: 0 | AD2: 0 | AE2: 0 | AF2: 0 | AG2: 0 | AH2: 0 | AI2: 0 | AJ2: 0 | AK2: 0 | AL2: 0 | AM2: 0 | AN2: 0 | AO2: 0 | AP2: 0 | AQ2: 0 | AR2: 0 | AS2: 0 | AT2: 0 | AU2: 0 | AV2: 0 | AW2: 0 | AX2: 0 | AY2: 0 | AZ2: 0 | BA2: 0 | BB2: 0 | BC2: 0 | BD2: 0 | BE2: 0 | BF2: 0 | BG2: 0 | BH2: 0 | BI2: 0 | BJ2: 0 | BK2: 0 | BL2: 0 | BM2: 0 | BN2: 0 | BO2: 0 | BP2: 0 | BQ2: 0 | BR2: 0 | BS2: 0 | BT2: 0 | BU2: 0 | BV2: 0 | BW2: 0 | BX2: 0 | BY2: 0 | BZ2: 0 | CA2: 0 | CB2: 0 | CC2: 0 | CD2: 0 | CE2: 0 | CF2: 0 | CG2: 0 | CH2: 0 | CI2: 0 | CJ2: 0 | CK2: 0 | CL2: 1 | CM2: 0 | CN2: 0 | CO2: 0 | CP2: 0 | CQ2: 0 | CR2: 0 | CS2: 0 | CT2: 0 | CU2: 0 | CV2: 0 | CW2: 0 | CX2: 0 | CY2: 0 | CZ2: 0 | DA2: 0 | DB2: 0 | DC2: 0 | DD2: 0 | DE2: 0 | DF2: 0 | DG2: 0 | DH2: 0 | DI2: 0 | DJ2: 0 | DK2: 0 | DL2: 0 | DM2: 0 | DN2: 0 | DO2: 0 | DP2: 0 | DQ2: 0 | DR2: 0 | DS2: 0 | DT2: 0 | DU2: 0 | DV2: 0 | DW2: 0 | DX2: 0 | DY2: 0 | DZ2: 0 | EA2: 0
A3: =VLOOKUP(E3,'Validation List'!F2:G397,2,FALSE) -> January | B3: =INDEX('NEW HIRE ROSTER'!$G:$G,MATCH(RAW!F3,'NEW HIRE ROSTER'!$A:$A,0)) -> RAMP | C3: =INDEX('NEW HIRE ROSTER'!$F:$F,MATCH(RAW!F3,'NEW HIRE ROSTER'!$A:$A,0)) -> Class 10 | D3: =INDEX('Validation List'!$H:$H,MATCH(RAW!E3,'Validation List'!$F:$F,0)) -> Jan Week 1 | E3: 45663 | F3: Bihag,Floriebel Dellona | G3: =VLOOKUP(F3,ML!C3:D589,2,FALSE) -> Jeric Amazona Mansibang | H3: =VLOOKUP(F3,ML!C3:E589,3,FALSE) -> QC | I3: Santos,Jennilyn Chan | J3: Provider | K3: "Call - Related to PA" | L3: INQ-E896400 | M3: 0.97 | N3: 0 | O3: 0 | P3: 0 | Q3: 0 | R3: 0 | S3: 0 | T3: 0 | U3: 0 | V3: 0 | W3: 0 | X3: 0 | Y3: 0 | Z3: 0 | AA3: 0 | AB3: 0 | AC3: 0 | AD3: 0 | AE3: 0 | AF3: 0 | AG3: 0 | AH3: 0 | AI3: 0 | AJ3: 0 | AK3: 0 | AL3: 0 | AM3: 0 | AN3: 0 | AO3: 0 | AP3: 0 | AQ3: 0 | AR3: 0 | AS3: 0 | AT3: 0 | AU3: 0 | AV3: 0 | AW3: 0 | AX3: 0 | AY3: 0 | AZ3: 0 | BA3: 0 | BB3: 0 | BC3: 0 | BD3: 0 | BE3: 0 | BF3: 0 | BG3: 0 | BH3: 0 | BI3: 0 | BJ3: 0 | BK3: 0 | BL3: 0 | BM3: 0 | BN3: 0 | BO3: 0 | BP3: 0 | BQ3: 0 | BR3: 0 | BS3: 0 | BT3: 0 | BU3: 0 | BV3: 0 | BW3: 0 | BX3: 0 | BY3: 0 | BZ3: 0 | CA3: 0 | CB3: 0 | CC3: 0 | CD3: 0 | CE3: 0 | CF3: 0 | CG3: 0 | CH3: 0 | CI3: 0 | CJ3: 0 | CK3: 0 | CL3: 1 | CM3: 0 | CN3: 0 | CO3: 0 | CP3: 0 | CQ3: 0 | CR3: 0 | CS3: 0 | CT3: 0 | CU3: 0 | CV3: 0 | CW3: 0 | CX3: 0 | CY3: 0 | CZ3: 0 | DA3: 0 | DB3: 0 | DC3: 0 | DD3: 0 | DE3: 0 | DF3: 0 | DG3: 0 | DH3: 0 | DI3: 0 | DJ3: 0 | DK3: 0 | DL3: 0 | DM3: 0 | DN3: 0 | DO3: 0 | DP3: 0 | DQ3: 0 | DR3: 0 | DS3: 0 | DT3: 0 | DU3: 0 | DV3: 0 | DW3: 0 | DX3: 0 | DY3: 0 | DZ3: 0 | EA3: 0
A4: =VLOOKUP(E4,'Validation List'!F3:G398,2,FALSE) -> January | B4: =INDEX('NEW HIRE ROSTER'!$G:$G,MATCH(RAW!F4,'NEW HIRE ROSTER'!$A:$A,0)) -> RAMP | C4: =INDEX('NEW HIRE ROSTER'!$F:$F,MATCH(RAW!F4,'NEW HIRE ROSTER'!$A:$A,0)) -> Class 10 | D4: =INDEX('Validation List'!$H:$H,MATCH(RAW!E4,'Validation List'!$F:$F,0)) -> Jan Week 1 | E4: 45664 | F4: Tejada,Jan Jaycle Javillonar | G4: =VLOOKUP(F4,ML!C4:D590,2,FALSE) -> Jeric Amazona Mansibang | H4: =VLOOKUP(F4,ML!C4:E590,3,FALSE) -> QC | I4: Santos,Jennilyn Chan | J4: Provider | K4: New PA Initiation | L4: INQ-E920853 | M4: 0.84 | N4: 0 | O4: 0 | P4: 0 | Q4: 0 | R4: 0 | S4: 0 | T4: 0 | U4: 0 | V4: 0 | W4: 0 | X4: 0 | Y4: 0 | Z4: 0 | AA4: 0 | AB4: 0 | AC4: 0 | AD4: 0 | AE4: 0 | AF4: 0 | AG4: 0 | AH4: 0 | AI4: 0 | AJ4: 0 | AK4: 0 | AL4: 0 | AM4: 0 | AN4: 0 | AO4: 0 | AP4: 0 | AQ4: 0 | AR4: 0 | AS4: 0 | AT4: 0 | AU4: 0 | AV4: 0 | AW4: 0 | AX4: 0 | AY4: 0 | AZ4: 0 | BA4: 0 | BB4: 0 | BC4: 0 | BD4: 0 | BE4: 0 | BF4: 0 | BG4: 0 | BH4: 0 | BI4: 0 | BJ4: 0 | BK4: 1 | BL4: 0 | BM4: 0 | BN4: 0 | BO4: 0 | BP4: 0 | BQ4: 0 | BR4: 0 | BS4: 0 | BT4: 0 | BU4: 0 | BV4: 0 | BW4: 0 | BX4: 0 | BY4: 0 | BZ4: 0 | CA4: 0 | CB4: 0 | CC4: 0 | CD4: 0 | CE4: 0 | CF4: 0 | CG4: 0 | CH4: 0 | CI4: 0 | CJ4: 0 | CK4: 0 | CL4: 0 | CM4: 0 | CN4: 0 | CO4: 0 | CP4: 0 | CQ4: 0 | CR4: 0 | CS4: 0 | CT4: 0 | CU4: 0 | CV4: 0 | CW4: 0 | CX4: 0 | CY4: 0 | CZ4: 0 | DA4: 0 | DB4: 0 | DC4: 0 | DD4: 0 | DE4: 0 | DF4: 1 | DG4: 0 | DH4: 0 | DI4: 0 | DJ4: 0 | DK4: 0 | DL4: 0 | DM4: 0 | DN4: 0 | DO4: 0 | DP4: 0 | DQ4: 0 | DR4: 0 | DS4: 0 | DT4: 0 | DU4: 0 | DV4: 0 | DW4: 0 | DX4: 0 | DY4: 0 | DZ4: 0 | EA4: 0
A5: =VLOOKUP(E5,'Validation List'!F4:G399,2,FALSE) -> January | B5: =INDEX('NEW HIRE ROSTER'!$G:$G,MATCH(RAW!F5,'NEW HIRE ROSTER'!$A:$A,0)) -> Nesting | C5: =INDEX('NEW HIRE ROSTER'!$F:$F,MATCH(RAW!F5,'NEW HIRE ROSTER'!$A:$A,0)) -> Class 11.1 | D5: =INDEX('Validation List'!$H:$H,MATCH(RAW!E5,'Validation List'!$F:$F,0)) -> Jan Week 1 | E5: 45665 | F5: Casoco,Carlito Trinidad | G5: =VLOOKUP(F5,ML!C5:D591,2,FALSE) -> Robin Antolihao Llamido | H5: =VLOOKUP(F5,ML!C5:E591,3,FALSE) -> QC | I5: Relon,Gazel De Guzman | J5: Provider | K5: "Status Check-Approved- Edit required" | L5: INQ-E942381 | M5: 1 | N5: 0 | O5: 0 | P5: 0 | Q5: 0 | R5: 0 | S5: 0 | T5: 0 | U5: 0 | V5: 0 | W5: 0 | X5: 0 | Y5: 0 | Z5: 0 | AA5: 0 | AB5: 0 | AC5: 0 | AD5: 0 | AE5: 0 | AF5: 0 | AG5: 0 | AH5: 0 | AI5: 0 | AJ5: 0 | AK5: 0 | AL5: 0 | AM5: 0 | AN5: 0 | AO5: 0 | AP5: 0 | AQ5: 0 | AR5: 0 | AS5: 0 | AT5: 0 | AU5: 0 | AV5: 0 | AW5: 0 | AX5: 0 | AY5: 0 | AZ5: 0 | BA5: 0 | BB5: 0 | BC5: 0 | BD5: 0 | BE5: 0 | BF5: 0 | BG5: 0 | BH5: 0 | BI5: 0 | BJ5: 0 | BK5: 0 | BL5: 0 | BM5: 0 | BN5: 0 | BO5: 0 | BP5: 0 | BQ5: 0 | BR5: 0 | BS5: 0 | BT5: 0 | BU5: 0 | BV5: 0 | BW5: 0 | BX5: 0 | BY5: 0 | BZ5: 0 | CA5: 0 | CB5: 0 | CC5: 0 | CD5: 0 | CE5: 0 | CF5: 0 | CG5: 0 | CH5: 0 | CI5: 0 | CJ5: 0 | CK5: 0 | CL5: 0 | CM5: 0 | CN5: 0 | CO5: 0 | CP5: 0 | CQ5: 0 | CR5: 0 | CS5: 0 | CT5: 0 | CU5: 0 | CV5: 0 | CW5: 0 | CX5: 0 | CY5: 0 | CZ5: 0 | DA5: 0 | DB5: 0 | DC5: 0 | DD5: 0 | DE5: 0 | DF5: 0 | DG5: 0 | DH5: 0 | DI5: 0 | DJ5: 0 | DK5: 0 | DL5: 0 | DM5: 0 | DN5: 0 | DO5: 0 | DP5: 0 | DQ5: 0 | DR5: 0 | DS5: 0 | DT5: 0 | DU5: 0 | DV5: 0 | DW5: 0 | DX5: 0 | DY5: 0 | DZ5: 0 | EA5: 0
A6: =VLOOKUP(E6,'Validation List'!F5:G400,2,FALSE) -> January | B6: =INDEX('NEW HIRE ROSTER'!$G:$G,MATCH(RAW!F6,'NEW HIRE ROSTER'!$A:$A,0)) -> RAMP | C6: =INDEX('NEW HIRE ROSTER'!$F:$F,MATCH(RAW!F6,'NEW HIRE ROSTER'!$A:$A,0)) -> Class 10 | D6: =INDEX('Validation List'!$H:$H,MATCH(RAW!E6,'Validation List'!$F:$F,0)) -> Jan Week 1 | E6: 45665 | F6: Mama,Monisah Cacasi | G6: =VLOOKUP(F6,ML!C6:D592,2,FALSE) -> Jeric Amazona Mansibang | H6: =VLOOKUP(F6,ML!C6:E592,3,FALSE) -> QC | I6: Santos,Jennilyn Chan | J6: Provider | K6: "Call - Related to PA" | L6: INQ-E938548 | M6: 0.84 | N6: 0 | O6: 0 | P6: 0 | Q6: 0 | R6: 0 | S6: 0 | T6: 0 | U6: 1 | V6: 0 | W6: 0 | X6: 0 | Y6: 0 | Z6: 0 | AA6: 0 | AB6: 0 | AC6: 0 | AD6: 0 | AE6: 0 | AF6: 0 | AG6: 0 | AH6: 0 | AI6: 0 | AJ6: 0 | AK6: 0 | AL6: 0 | AM6: 0 | AN6: 0 | AO6: 0 | AP6: 0 | AQ6: 0 | AR6: 0 | AS6: 0 | AT6: 0 | AU6: 0 | AV6: 0 | AW6: 0 | AX6: 0 | AY6: 0 | AZ6: 0 | BA6: 0 | BB6: 0 | BC6: 0 | BD6: 0 | BE6: 0 | BF6: 0 | BG6: 0 | BH6: 0 | BI6: 0 | BJ6: 0 | BK6: 0 | BL6: 0 | BM6: 0 | BN6: 0 | BO6: 0 | BP6: 0 | BQ6: 0 | BR6: 0 | BS6: 0 | BT6: 0 | BU6: 0 | BV6: 0 | BW6: 0 | BX6: 0 | BY6: 0 | BZ6: 0 | CA6: 0 | CB6: 0 | CC6: 0 | CD6: 0 | CE6: 0 | CF6: 0 | CG6: 0 | CH6: 0 | CI6: 0 | CJ6: 0 | CK6: 0 | CM6: 0 | CN6: 0 | CO6: 0 | CP6: 0 | CQ6: 0 | CR6: 0 | CS6: 0 | CT6: 0 | CU6: 0 | CV6: 0 | CW6: 0 | CX6: 0 | CY6: 0 | CZ6: 0 | DA6: 0 | DB6: 0 | DC6: 0 | DD6: 0 | DE6: 0 | DF6: 1 | DG6: 0 | DH6: 0 | DI6: 0 | DJ6: 0 | DK6: 0 | DL6: 0 | DM6: 0 | DN6: 0 | DO6: 0 | DP6: 0 | DQ6: 0 | DR6: 0 | DS6: 0 | DT6: 0 | DU6: 0 | DV6: 0 | DW6: 0 | DX6: 0 | DY6: 0 | DZ6: 0 | EA6: 0
A7: =VLOOKUP(E7,'Validation List'!F7:G402,2,FALSE) -> January | B7: =INDEX('NEW HIRE ROSTER'!$G:$G,MATCH(RAW!F7,'NEW HIRE ROSTER'!$A:$A,0)) -> RAMP | C7: =INDEX('NEW HIRE ROSTER'!$F:$F,MATCH(RAW!F7,'NEW HIRE ROSTER'!$A:$A,0)) -> Class 10 | D7: =INDEX('Validation List'!$H:$H,MATCH(RAW!E7,'Validation List'!$F:$F,0)) -> Jan Week 1 | E7: 45663 | F7: Bihag,Floriebel Dellona | G7: =VLOOKUP(F7,ML!C7:D593,2,FALSE) -> Jeric Amazona Mansibang | H7: =VLOOKUP(F7,ML!C8:E594,3,FALSE) -> QC | I7: Santos,Jennilyn Chan | J7: Provider | K7: "Call - Related to PA" | L7: INQ-E895822 | M7: 1 | N7: 0 | O7: 0 | P7: 0 | Q7: 0 | R7: 0 | S7: 0 | T7: 0 | U7: 0 | V7: 0 | W7: 0 | X7: 0 | Y7: 0 | Z7: 0 | AA7: 0 | AB7: 0 | AC7: 0 | AD7: 0 | AE7: 0 | AF7: 0 | AG7: 0 | AH7: 0 | AI7: 0 | AJ7: 0 | AK7: 0 | AL7: 0 | AM7: 0 | AN7: 0 | AO7: 0 | AP7: 0 | AQ7: 0 | AR7: 0 | AS7: 0 | AT7: 0 | AU7: 0 | AV7: 0 | AW7: 0 | AX7: 0 | AY7: 0 | AZ7: 0 | BA7: 0 | BB7: 0 | BC7: 0 | BD7: 0 | BE7: 0 | BF7: 0 | BG7: 0 | BH7: 0 | BI7: 0 | BJ7: 0 | BK7: 0 | BL7: 0 | BM7: 0 | BN7: 0 | BO7: 0 | BP7: 0 | BQ7: 0 | BR7: 0 | BS7: 0 | BT7: 0 | BU7: 0 | BV7: 0 | BW7: 0 | BX7: 0 | BY7: 0 | BZ7: 0 | CA7: 0 | CB7: 0 | CC7: 0 | CD7: 0 | CE7: 0 | CF7: 0 | CG7: 0 | CH7: 0 | CI7: 0 | CJ7: 0 | CK7: 0 | CL7: 0 | CM7: 0 | CN7: 0 | CO7: 0 | CP7: 0 | CQ7: 0 | CR7: 0 | CS7: 0 | CT7: 0 | CU7: 0 | CV7: 0 | CW7: 0 | CX7: 0 | CY7: 0 | CZ7: 0 | DA7: 0 | DB7: 0 | DC7: 0 | DD7: 0 | DE7: 0 | DF7: 0 | DG7: 0 | DH7: 0 | DI7: 0 | DJ7: 0 | DK7: 0 | DL7: 0 | DM7: 0 | DN7: 0 | DO7: 0 | DP7: 0 | DQ7: 0 | DR7: 0 | DS7: 0 | DT7: 0 | DU7: 0 | DV7: 0 | DW7: 0 | DX7: 0 | DY7: 0 | DZ7: 0 | EA7: 0
A8: =VLOOKUP(E8,'Validation List'!F8:G403,2,FALSE) -> January | B8: =INDEX('NEW HIRE ROSTER'!$G:$G,MATCH(RAW!F8,'NEW HIRE ROSTER'!$A:$A,0)) -> RAMP | C8: =INDEX('NEW HIRE ROSTER'!$F:$F,MATCH(RAW!F8,'NEW HIRE ROSTER'!$A:$A,0)) -> Class 10 | D8: =INDEX('Validation List'!$H:$H,MATCH(RAW!E8,'Validation List'!$F:$F,0)) -> Jan Week 1 | E8: 45663 | F8: Bihag,Floriebel Dellona | G8: =VLOOKUP(F8,ML!C8:D594,2,FALSE) -> Jeric Amazona Mansibang | H8: =VLOOKUP(F8,ML!C9:E595,3,FALSE) -> QC | I8: Santos,Jennilyn Chan | J8: Provider | K8: "Call - Related to PA" | L8: INQ-E896100 | M8: 1 | N8: 0 | O8: 0 | P8: 0 | Q8: 0 | R8: 0 | S8: 0 | T8: 0 | U8: 0 | V8: 0 | W8: 0 | X8: 0 | Y8: 0 | Z8: 0 | AA8: 0 | AB8: 0 | AC8: 0 | AD8: 0 | AE8: 0 | AF8: 0 | AG8: 0 | AH8: 0 | AI8: 0 | AJ8: 0 | AK8: 0 | AL8: 0 | AM8: 0 | AN8: 0 | AO8: 0 | AP8: 0 | AQ8: 0 | AR8: 0 | AS8: 0 | AT8: 0 | AU8: 0 | AV8: 0 | AW8: 0 | AX8: 0 | AY8: 0 | AZ8: 0 | BA8: 0 | BB8: 0 | BC8: 0 | BD8: 0 | BE8: 0 | BF8: 0 | BG8: 0 | BH8: 0 | BI8: 0 | BJ8: 0 | BK8: 0 | BL8: 0 | BM8: 0 | BN8: 0 | BO8: 0 | BP8: 0 | BQ8: 0 | BR8: 0 | BS8: 0 | BT8: 0 | BU8: 0 | BV8: 0 | BW8: 0 | BX8: 0 | BY8: 0 | BZ8: 0 | CA8: 0 | CB8: 0 | CC8: 0 | CD8: 0 | CE8: 0 | CF8: 0 | CG8: 0 | CH8: 0 | CI8: 0 | CJ8: 0 | CK8: 0 | CL8: 0 | CM8: 0 | CN8: 0 | CO8: 0 | CP8: 0 | CQ8: 0 | CR8: 0 | CS8: 0 | CT8: 0 | CU8: 0 | CV8: 0 | CW8: 0 | CX8: 0 | CY8: 0 | CZ8: 0 | DA8: 0 | DB8: 0 | DC8: 0 | DD8: 0 | DE8: 0 | DF8: 0 | DG8: 0 | DH8: 0 | DI8: 0 | DJ8: 0 | DK8: 0 | DL8: 0 | DM8: 0 | DN8: 0 | DO8: 0 | DP8: 0 | DQ8: 0 | DR8: 0 | DS8: 0 | DT8: 0 | DU8: 0 | DV8: 0 | DW8: 0 | DX8: 0 | DY8: 0 | DZ8: 0 | EA8: 0
A9: =VLOOKUP(E9,'Validation List'!F9:G404,2,FALSE) -> January | B9: =INDEX('NEW HIRE ROSTER'!$G:$G,MATCH(RAW!F9,'NEW HIRE ROSTER'!$A:$A,0)) -> RAMP | C9: =INDEX('NEW HIRE ROSTER'!$F:$F,MATCH(RAW!F9,'NEW HIRE ROSTER'!$A:$A,0)) -> Class 9.1 | D9: =INDEX('Validation List'!$H:$H,MATCH(RAW!E9,'Validation List'!$F:$F,0)) -> Jan Week 1 | E9: 45664 | F9: Ramos,Chester Irvin Bautista | G9: =VLOOKUP(F9,ML!C9:D595,2,FALSE) -> John Earl Melitado Lagare | H9: =VLOOKUP(F9,ML!C10:E596,3,FALSE) -> QC | I9: Gatchalian,Ernie Marie Caburian | J9: Provider | K9: "Call Transferred" | L9: INQ-E921924 | M9: 1 | N9: 0 | O9: 0 | P9: 0 | Q9: 0 | R9: 0 | S9: 0 | T9: 0 | U9: 0 | V9: 0 | W9: 0 | X9: 0 | Y9: 0 | Z9: 0 | AA9: 0 | AB9: 0 | AC9: 0 | AD9: 0 | AE9: 0 | AF9: 0 | AG9: 0 | AH9: 0 | AI9: 0 | AJ9: 0 | AK9: 0 | AL9: 0 | AM9: 0 | AN9: 0 | AO9: 0 | AP9: 0 | AQ9: 0 | AR9: 0 | AS9: 0 | AT9: 0 | AU9: 0 | AV9: 0 | AW9: 0 | AX9: 0 | AY9: 0 | AZ9: 0 | BA9: 0 | BB9: 0 | BC9: 0 | BD9: 0 | BE9: 0 | BF9: 0 | BG9: 0 | BH9: 0 | BI9: 0 | BJ9: 0 | BK9: 0 | BL9: 0 | BM9: 0 | BN9: 0 | BO9: 0 | BP9: 0 | BQ9: 0 | BR9: 0 | BS9: 0 | BT9: 0 | BU9: 0 | BV9: 0 | BW9: 0 | BX9: 0 | BY9: 0 | BZ9: 0 | CA9: 0 | CB9: 0 | CC9: 0 | CD9: 0 | CE9: 0 | CF9: 0 | CG9: 0 | CH9: 0 | CI9: 0 | CJ9: 0 | CK9: 0 | CL9: 0 | CM9: 0 | CN9: 0 | CO9: 0 | CP9: 0 | CQ9: 0 | CR9: 0 | CS9: 0 | CT9: 0 | CU9: 0 | CV9: 0 | CW9: 0 | CX9: 0 | CY9: 0 | CZ9: 0 | DA9: 0 | DB9: 0 | DC9: 0 | DD9: 0 | DE9: 0 | DF9: 0 | DG9: 0 | DH9: 0 | DI9: 0 | DJ9: 0 | DK9: 0 | DL9: 0 | DM9: 0 | DN9: 0 | DO9: 0 | DP9: 0 | DQ9: 0 | DR9: 0 | DS9: 0 | DT9: 0 | DU9: 0 | DV9: 0 | DW9: 0 | DX9: 0 | DY9: 0 | DZ9: 0 | EA9: 0
A10: =VLOOKUP(E10,'Validation List'!F10:G405,2,FALSE) -> January | B10: =INDEX('NEW HIRE ROSTER'!$G:$G,MATCH(RAW!F10,'NEW HIRE ROSTER'!$A:$A,0)) -> RAMP | C10: =INDEX('NEW HIRE ROSTER'!$F:$F,MATCH(RAW!F10,'NEW HIRE ROSTER'!$A:$A,0)) -> Class 10 | D10: =INDEX('Validation List'!$H:$H,MATCH(RAW!E10,'Validation List'!$F:$F,0)) -> Jan Week 1 | E10: 45664 | F10: Tejada,Jan Jaycle Javillonar | G10: =VLOOKUP(F10,ML!C10:D596,2,FALSE) -> Jeric Amazona Mansibang | H10: =VLOOKUP(F10,ML!C11:E597,3,FALSE) -> QC | I10: Santos,Jennilyn Chan | J10: Provider | K10: "Call Transferred" | L10: INQ-E922636 | M10: 1 | N10: 0 | O10: 0 | P10: 0 | Q10: 0 | R10: 0 | S10: 0 | T10: 0 | U10: 0 | V10: 0 | W10: 0 | X10: 0 | Y10: 0 | Z10: 0 | AA10: 0 | AB10: 0 | AC10: 0 | AD10: 0 | AE10: 0 | AF10: 0 | AG10: 0 | AH10: 0 | AI10: 0 | AJ10: 0 | AK10: 0 | AL10: 0 | AM10: 0 | AN10: 0 | AO10: 0 | AP10: 0 | AQ10: 0 | AR10: 0 | AS10: 0 | AT10: 0 | AU10: 0 | AV10: 0 | AW10: 0 | AX10: 0 | AY10: 0 | AZ10: 0 | BA10: 0 | BB10: 0 | BC10: 0 | BD10: 0 | BE10: 0 | BF10: 0 | BG10: 0 | BH10: 0 | BI10: 0 | BJ10: 0 | BK10: 0 | BL10: 0 | BM10: 0 | BN10: 0 | BO10: 0 | BP10: 0 | BQ10: 0 | BR10: 0 | BS10: 0 | BT10: 0 | BU10: 0 | BV10: 0 | BW10: 0 | BX10: 0 | BY10: 0 | BZ10: 0 | CA10: 0 | CB10: 0 | CC10: 0 | CD10: 0 | CE10: 0 | CF10: 0 | CG10: 0 | CH10: 0 | CI10: 0 | CJ10: 0 | CK10: 0 | CL10: 0 | CM10: 0 | CN10: 0 | CO10: 0 | CP10: 0 | CQ10: 0 | CR10: 0 | CS10: 0 | CT10: 0 | CU10: 0 | CV10: 0 | CW10: 0 | CX10: 0 | CY10: 0 | CZ10: 0 | DA10: 0 | DB10: 0 | DC10: 0 | DD10: 0 | DE10: 0 | DF10: 0 | DG10: 0 | DH10: 0 | DI10: 0 | DJ10: 0 | DK10: 0 | DL10: 0 | DM10: 0 | DN10: 0 | DO10: 0 | DP10: 0 | DQ10: 0 | DR10: 0 | DS10: 0 | DT10: 0 | DU10: 0 | DV10: 0 | DW10: 0 | DX10: 0 | DY10: 0 | DZ10: 0 | EA10: 0
A11: =VLOOKUP(E11,'Validation List'!F11:G406,2,FALSE) -> January | B11: =INDEX('NEW HIRE ROSTER'!$G:$G,MATCH(RAW!F11,'NEW HIRE ROSTER'!$A:$A,0)) -> Nesting | C11: =INDEX('NEW HIRE ROSTER'!$F:$F,MATCH(RAW!F11,'NEW HIRE ROSTER'!$A:$A,0)) -> Class 11.1 | D11: =INDEX('Validation List'!$H:$H,MATCH(RAW!E11,'Validation List'!$F:$F,0)) -> Jan Week 1 | E11: 45665 | F11: Candelaria,Tyronne Tillain | G11: =VLOOKUP(F11,ML!C11:D597,2,FALSE) -> Robin Antolihao Llamido | H11: =VLOOKUP(F11,ML!C12:E598,3,FALSE) -> QC | I11: Logmao,Nyrene Grace Lozada | J11: Provider | K11: "Call Transferred" | L11: N/A | M11: 1 | N11: 0 | O11: 0 | P11: 0 | Q11: 0 | R11: 0 | S11: 0 | T11: 0 | U11: 0 | V11: 0 | W11: 0 | X11: 0 | Y11: 0 | Z11: 0 | AA11: 0 | AB11: 0 | AC11: 0 | AD11: 0 | AE11: 0 | AF11: 0 | AG11: 0 | AH11: 0 | AI11: 0 | AJ11: 0 | AK11: 0 | AL11: 0 | AM11: 0 | AN11: 0 | AO11: 0 | AP11: 0 | AQ11: 0 | AR11: 0 | AS11: 0 | AT11: 0 | AU11: 0 | AV11: 0 | AW11: 0 | AX11: 0 | AY11: 0 | AZ11: 0 | BA11: 0 | BB11: 0 | BC11: 0 | BD11: 0 | BE11: 0 | BF11: 0 | BG11: 0 | BH11: 0 | BI11: 0 | BJ11: 0 | BK11: 0 | BL11: 0 | BM11: 0 | BN11: 0 | BO11: 0 | BP11: 0 | BQ11: 0 | BR11: 0 | BS11: 0 | BT11: 0 | BU11: 0 | BV11: 0 | BW11: 0 | BX11: 0 | BY11: 0 | BZ11: 0 | CA11: 0 | CB11: 0 | CC11: 0 | CD11: 0 | CE11: 0 | CF11: 0 | CG11: 0 | CH11: 0 | CI11: 0 | CJ11: 0 | CK11: 0 | CL11: 0 | CM11: 0 | CN11: 0 | CO11: 0 | CP11: 0 | CQ11: 0 | CR11: 0 | CS11: 0 | CT11: 0 | CU11: 0 | CV11: 0 | CW11: 0 | CX11: 0 | CY11: 0 | CZ11: 0 | DA11: 0 | DB11: 0 | DC11: 0 | DD11: 0 | DE11: 0 | DF11: 0 | DG11: 0 | DH11: 0 | DI11: 0 | DJ11: 0 | DK11: 0 | DL11: 0 | DM11: 0 | DN11: 0 | DO11: 0 | DP11: 0 | DQ11: 0 | DR11: 0 | DS11: 0 | DT11: 0 | DU11: 0 | DV11: 0 | DW11: 0 | DX11: 0 | DY11: 0 | DZ11: 0 | EA11: 0
A12: =VLOOKUP(E12,'Validation List'!F13:G408,2,FALSE) -> January | B12: =INDEX('NEW HIRE ROSTER'!$G:$G,MATCH(RAW!F12,'NEW HIRE ROSTER'!$A:$A,0)) -> RAMP | C12: =INDEX('NEW HIRE ROSTER'!$F:$F,MATCH(RAW!F12,'NEW HIRE ROSTER'!$A:$A,0)) -> Class 10 | D12: =INDEX('Validation List'!$H:$H,MATCH(RAW!E12,'Validation List'!$F:$F,0)) -> Jan Week 1 | E12: 45665 | F12: Mama,Monisah Cacasi | G12: =VLOOKUP(F12,ML!C12:D598,2,FALSE) -> Jeric Amazona Mansibang | H12: =VLOOKUP(F12,ML!C14:E600,3,FALSE) -> QC | I12: Santos,Jennilyn Chan | J12: Provider | K12: New PA Initiation | L12: INQ-E939796 | M12: 1 | N12: 0 | O12: 0 | P12: 0 | Q12: 0 | R12: 0 | S12: 0 | T12: 0 | U12: 0 | V12: 0 | W12: 0 | X12: 0 | Y12: 0 | Z12: 0 | AA12: 0 | AB12: 0 | AC12: 0 | AD12: 0 | AE12: 0 | AF12: 0 | AG12: 0 | AH12: 0 | AI12: 0 | AJ12: 0 | AK12: 0 | AL12: 0 | AM12: 0 | AN12: 0 | AO12: 0 | AP12: 0 | AQ12: 0 | AR12: 0 | AS12: 0 | AT12: 0 | AU12: 0 | AV12: 0 | AW12: 0 | AX12: 0 | AY12: 0 | AZ12: 0 | BA12: 0 | BB12: 0 | BC12: 0 | BD12: 0 | BE12: 0 | BF12: 0 | BG12: 0 | BH12: 0 | BI12: 0 | BJ12: 0 | BK12: 0 | BL12: 0 | BM12: 0 | BN12: 0 | BO12: 0 | BP12: 0 | BQ12: 0 | BR12: 0 | BS12: 0 | BT12: 0 | BU12: 0 | BV12: 0 | BW12: 0 | BX12: 0 | BY12: 0 | BZ12: 0 | CA12: 0 | CB12: 0 | CC12: 0 | CD12: 0 | CE12: 0 | CF12: 0 | CG12: 0 | CH12: 0 | CI12: 0 | CJ12: 0 | CK12: 0 | CL12: 0 | CM12: 0 | CN12: 0 | CO12: 0 | CP12: 0 | CQ12: 0 | CR12: 0 | CS12: 0 | CT12: 0 | CU12: 0 | CV12: 0 | CW12: 0 | CX12: 0 | CY12: 0 | CZ12: 0 | DA12: 0 | DB12: 0 | DC12: 0 | DD12: 0 | DE12: 0 | DF12: 0 | DG12: 0 | DH12: 0 | DI12: 0 | DJ12: 0 | DK12: 0 | DL12: 0 | DM12: 0 | DN12: 0 | DO12: 0 | DP12: 0 | DQ12: 0 | DR12: 0 | DS12: 0 | DT12: 0 | DU12: 0 | DV12: 0 | DW12: 0 | DX12: 0 | DY12: 0 | DZ12: 0 | EA12: 0
A13: =VLOOKUP(E13,'Validation List'!F14:G409,2,FALSE) -> January | B13: =INDEX('NEW HIRE ROSTER'!$G:$G,MATCH(RAW!F13,'NEW HIRE ROSTER'!$A:$A,0)) -> RAMP | C13: =INDEX('NEW HIRE ROSTER'!$F:$F,MATCH(RAW!F13,'NEW HIRE ROSTER'!$A:$A,0)) -> Class 10 | D13: =INDEX('Validation List'!$H:$H,MATCH(RAW!E13,'Validation List'!$F:$F,0)) -> Jan Week 1 | E13: 45665 | F13: Lumabao,Rein Amyl Montanez | G13: =VLOOKUP(F13,ML!C13:D599,2,FALSE) -> Jeric Amazona Mansibang | H13: =VLOOKUP(F13,ML!C15:E601,3,FALSE) -> QC | I13: Santos,Jennilyn Chan | J13: Provider | K13: "Call - Related to PA" | L13: INQ-E945758 | M13: 1 | N13: 0 | O13: 0 | P13: 0 | Q13: 0 | R13: 0 | S13: 0 | T13: 0 | U13: 0 | V13: 0 | W13: 0 | X13: 0 | Y13: 0 | Z13: 0 | AA13: 0 | AB13: 0 | AC13: 0 | AD13: 0 | AE13: 0 | AF13: 0 | AG13: 0 | AH13: 0 | AI13: 0 | AJ13: 0 | AK13: 0 | AL13: 0 | AM13: 0 | AN13: 0 | AO13: 0 | AP13: 0 | AQ13: 0 | AR13: 0 | AS13: 0 | AT13: 0 | AU13: 0 | AV13: 0 | AW13: 0 | AX13: 0 | AY13: 0 | AZ13: 0 | BA13: 0 | BB13: 0 | BC13: 0 | BD13: 0 | BE13: 0 | BF13: 0 | BG13: 0 | BH13: 0 | BI13: 0 | BJ13: 0 | BK13: 0 | BL13: 0 | BM13: 0 | BN13: 0 | BO13: 0 | BP13: 0 | BQ13: 0 | BR13: 0 | BS13: 0 | BT13: 0 | BU13: 0 | BV13: 0 | BW13: 0 | BX13: 0 | BY13: 0 | BZ13: 0 | CA13: 0 | CB13: 0 | CC13: 0 | CD13: 0 | CE13: 0 | CF13: 0 | CG13: 0 | CH13: 0 | CI13: 0 | CJ13: 0 | CK13: 0 | CL13: 0 | CM13: 0 | CN13: 0 | CO13: 0 | CP13: 0 | CQ13: 0 | CR13: 0 | CS13: 0 | CT13: 0 | CU13: 0 | CV13: 0 | CW13: 0 | CX13: 0 | CY13: 0 | CZ13: 0 | DA13: 0 | DB13: 0 | DC13: 0 | DD13: 0 | DE13: 0 | DF13: 0 | DG13: 0 | DH13: 0 | DI13: 0 | DJ13: 0 | DK13: 0 | DL13: 0 | DM13: 0 | DN13: 0 | DO13: 0 | DP13: 0 | DQ13: 0 | DR13: 0 | DS13: 0 | DT13: 0 | DU13: 0 | DV13: 0 | DW13: 0 | DX13: 0 | DY13: 0 | DZ13: 0 | EA13: 0
A14: =VLOOKUP(E14,'Validation List'!F15:G410,2,FALSE) -> January | B14: =INDEX('NEW HIRE ROSTER'!$G:$G,MATCH(RAW!F14,'NEW HIRE ROSTER'!$A:$A,0)) -> Nesting | C14: =INDEX('NEW HIRE ROSTER'!$F:$F,MATCH(RAW!F14,'NEW HIRE ROSTER'!$A:$A,0)) -> Class 11.1 | D14: =INDEX('Validation List'!$H:$H,MATCH(RAW!E14,'Validation List'!$F:$F,0)) -> Jan Week 1 | E14: 45666 | F14: Austria,Effie Galang | G14: =VLOOKUP(F14,ML!C14:D600,2,FALSE) -> Robin Antolihao Llamido | H14: =VLOOKUP(F14,ML!C16:E602,3,FALSE) -> QC | I14: Ongjoco,Hanna Crystal Azana | J14: Provider | K14: "Status Check-Denied" | L14: INQ-E970005 | M14: 0.94 | N14: 0 | O14: 0 | P14: 0 | Q14: 0 | R14: 0 | S14: 0 | T14: 0 | U14: 0 | V14: 0 | W14: 0 | X14: 1 | Y14: 0 | Z14: 0 | AA14: 0 | AB14: 0 | AC14: 0 | AD14: 0 | AE14: 0 | AF14: 0 | AG14: 0 | AH14: 0 | AI14: 0 | AJ14: 0 | AK14: 0 | AL14: 0 | AM14: 0 | AN14: 0 | AO14: 0 | AP14: 0 | AQ14: 0 | AR14: 0 | AS14: 0 | AT14: 0 | AU14: 0 | AV14: 0 | AW14: 0 | AX14: 0 | AY14: 0 | AZ14: 0 | BA14: 0 | BB14: 0 | BC14: 0 | BD14: 0 | BE14: 0 | BF14: 0 | BG14: 0 | BH14: 0 | BI14: 0 | BJ14: 0 | BK14: 0 | BL14: 0 | BM14: 0 | BN14: 0 | BO14: 0 | BP14: 0 | BQ14: 0 | BR14: 0 | BS14: 0 | BT14: 0 | BU14: 0 | BV14: 0 | BW14: 0 | BX14: 0 | BY14: 0 | BZ14: 0 | CA14: 0 | CB14: 0 | CC14: 0 | CD14: 0 | CE14: 0 | CF14: 0 | CG14: 0 | CH14: 0 | CI14: 0 | CJ14: 0 | CK14: 0 | CL14: 0 | CM14: 0 | CN14: 0 | CO14: 0 | CP14: 0 | CQ14: 0 | CR14: 0 | CS14: 0 | CT14: 0 | CU14: 0 | CV14: 0 | CW14: 0 | CX14: 0 | CY14: 0 | CZ14: 0 | DA14: 0 | DB14: 0 | DC14: 0 | DD14: 0 | DE14: 0 | DF14: 0 | DG14: 0 | DH14: 0 | DI14: 0 | DJ14: 0 | DK14: 0 | DL14: 0 | DM14: 0 | DN14: 0 | DO14: 0 | DP14: 0 | DQ14: 0 | DR14: 0 | DS14: 0 | DT14: 0 | DU14: 0 | DV14: 0 | DW14: 0 | DX14: 0 | DY14: 0 | DZ14: 0 | EA14: 0
A15: =VLOOKUP(E15,'Validation List'!F16:G411,2,FALSE) -> January | B15: =INDEX('NEW HIRE ROSTER'!$G:$G,MATCH(RAW!F15,'NEW HIRE ROSTER'!$A:$A,0)) -> Nesting | C15: =INDEX('NEW HIRE ROSTER'!$F:$F,MATCH(RAW!F15,'NEW HIRE ROSTER'!$A:$A,0)) -> Class 11.2 | D15: =INDEX('Validation List'!$H:$H,MATCH(RAW!E15,'Validation List'!$F:$F,0)) -> Jan Week 1 | E15: 45666 | F15: Tadaya,Frederic Palongpong | G15: =VLOOKUP(F15,ML!C15:D601,2,FALSE) -> Khyno Elimanco Cortez | H15: =VLOOKUP(F15,ML!C17:E603,3,FALSE) -> QC | I15: Gatchalian,Ernie Marie Caburian | J15: Provider | K15: "Call Transferred" | L15: INQ-E974427 | M15: 0.94 | N15: 0 | O15: 0 | P15: 0 | Q15: 0 | R15: 0 | S15: 0 | T15: 0 | U15: 0 | V15: 0 | W15: 0 | X15: 1 | Y15: 0 | Z15: 0 | AA15: 0 | AB15: 0 | AC15: 0 | AD15: 0 | AE15: 0 | AF15: 0 | AG15: 0 | AH15: 0 | AI15: 0 | AJ15: 0 | AK15: 0 | AL15: 0 | AM15: 0 | AN15: 0 | AO15: 0 | AP15: 0 | AQ15: 0 | AR15: 0 | AS15: 0 | AT15: 0 | AU15: 0 | AV15: 0 | AW15: 0 | AX15: 0 | AY15: 0 | AZ15: 0 | BA15: 0 | BB15: 0 | BC15: 0 | BD15: 0 | BE15: 0 | BF15: 0 | BG15: 0 | BH15: 0 | BI15: 0 | BJ15: 0 | BK15: 0 | BL15: 0 | BM15: 0 | BN15: 0 | BO15: 0 | BP15: 0 | BQ15: 0 | BR15: 0 | BS15: 0 | BT15: 0 | BU15: 0 | BV15: 0 | BW15: 0 | BX15: 0 | BY15: 0 | BZ15: 0 | CA15: 0 | CB15: 0 | CC15: 0 | CD15: 0 | CE15: 0 | CF15: 0 | CG15: 0 | CH15: 0 | CI15: 0 | CJ15: 0 | CK15: 0 | CL15: 0 | CM15: 0 | CN15: 0 | CO15: 0 | CP15: 0 | CQ15: 0 | CR15: 0 | CS15: 0 | CT15: 0 | CU15: 0 | CV15: 0 | CW15: 0 | CX15: 0 | CY15: 0 | CZ15: 0 | DA15: 0 | DB15: 0 | DC15: 0 | DD15: 0 | DE15: 0 | DF15: 0 | DG15: 0 | DH15: 0 | DI15: 0 | DJ15: 0 | DK15: 0 | DL15: 0 | DM15: 0 | DN15: 0 | DO15: 0 | DP15: 0 | DQ15: 0 | DR15: 0 | DS15: 0 | DT15: 0 | DU15: 0 | DV15: 0 | DW15: 0 | DX15: 0 | DY15: 0 | DZ15: 0 | EA15: 0
A16: =VLOOKUP(E16,'Validation List'!F17:G412,2,FALSE) -> January | B16: =INDEX('NEW HIRE ROSTER'!$G:$G,MATCH(RAW!F16,'NEW HIRE ROSTER'!$A:$A,0)) -> Nesting | C16: =INDEX('NEW HIRE ROSTER'!$F:$F,MATCH(RAW!F16,'NEW HIRE ROSTER'!$A:$A,0)) -> Class 11.2 | D16: =INDEX('Validation List'!$H:$H,MATCH(RAW!E16,'Validation List'!$F:$F,0)) -> Jan Week 1 | E16: 45666 | F16: Tabita,Czarina Manuel | G16: =VLOOKUP(F16,ML!C16:D602,2,FALSE) -> Khyno Elimanco Cortez | H16: =VLOOKUP(F16,ML!C18:E604,3,FALSE) -> QC | I16: Gatchalian,Ernie Marie Caburian | J16: Provider | K16: New PA Initiation | L16: PA-E2234004 | M16: 0.94 | N16: 0 | O16: 0 | P16: 0 | Q16: 0 | R16: 0 | S16: 0 | T16: 0 | U16: 0 | V16: 0 | W16: 0 | X16: 1 | Y16: 0 | Z16: 0 | AA16: 0 | AB16: 0 | AC16: 0 | AD16: 0 | AE16: 0 | AF16: 0 | AG16: 0 | AH16: 0 | AI16: 0 | AJ16: 0 | AK16: 0 | AL16: 0 | AM16: 0 | AN16: 0 | AO16: 0 | AP16: 0 | AQ16: 0 | AR16: 0 | AS16: 0 | AT16: 0 | AU16: 0 | AV16: 0 | AW16: 0 | AX16: 0 | AY16: 0 | AZ16: 0 | BA16: 0 | BB16: 0 | BC16: 0 | BD16: 0 | BE16: 0 | BF16: 0 | BG16: 0 | BH16: 0 | BI16: 0 | BJ16: 0 | BK16: 0 | BL16: 0 | BM16: 0 | BN16: 0 | BO16: 0 | BP16: 0 | BQ16: 0 | BR16: 0 | BS16: 0 | BT16: 0 | BU16: 0 | BV16: 0 | BW16: 0 | BX16: 0 | BY16: 0 | BZ16: 0 | CA16: 0 | CB16: 0 | CC16: 0 | CD16: 0 | CE16: 0 | CF16: 0 | CG16: 0 | CH16: 0 | CI16: 0 | CJ16: 0 | CK16: 0 | CL16: 0 | CM16: 0 | CN16: 0 | CO16: 0 | CP16: 0 | CQ16: 0 | CR16: 0 | CS16: 0 | CT16: 0 | CU16: 0 | CV16: 0 | CW16: 0 | CX16: 0 | CY16: 0 | CZ16: 0 | DA16: 0 | DB16: 0 | DC16: 0 | DD16: 0 | DE16: 0 | DF16: 0 | DG16: 0 | DH16: 0 | DI16: 0 | DJ16: 0 | DK16: 0 | DL16: 0 | DM16: 0 | DN16: 0 | DO16: 0 | DP16: 0 | DQ16: 0 | DR16: 0 | DS16: 0 | DT16: 0 | DU16: 0 | DV16: 0 | DW16: 0 | DX16: 0 | DY16: 0 | DZ16: 0 | EA16: 0
A17: =VLOOKUP(E17,'Validation List'!F18:G413,2,FALSE) -> January | B17: =INDEX('NEW HIRE ROSTER'!$G:$G,MATCH(RAW!F17,'NEW HIRE ROSTER'!$A:$A,0)) -> Nesting | C17: =INDEX('NEW HIRE ROSTER'!$F:$F,MATCH(RAW!F17,'NEW HIRE ROSTER'!$A:$A,0)) -> Class 11.2 | D17: =INDEX('Validation List'!$H:$H,MATCH(RAW!E17,'Validation List'!$F:$F,0)) -> Jan Week 1 | E17: 45667 | F17: Roque,Francis Anthony Jacobe | G17: =VLOOKUP(F17,ML!C17:D603,2,FALSE) -> Khyno Elimanco Cortez | H17: =VLOOKUP(F17,ML!C19:E605,3,FALSE) -> QC | I17: Gatchalian,Ernie Marie Caburian | J17: Provider | K17: "Call Transferred" | L17: INQ-E999677 | M17: 0.94 | N17: 0 | O17: 0 | P17: 0 | Q17: 0 | R17: 0 | S17: 0 | T17: 0 | U17: 1 | V17: 0 | W17: 0 | X17: 0 | Y17: 0 | Z17: 0 | AA17: 0 | AB17: 0 | AC17: 0 | AD17: 0 | AE17: 0 | AF17: 0 | AG17: 0 | AH17: 0 | AI17: 0 | AJ17: 0 | AK17: 0 | AL17: 0 | AM17: 0 | AN17: 0 | AO17: 0 | AP17: 0 | AQ17: 0 | AR17: 0 | AS17: 0 | AT17: 0 | AU17: 0 | AV17: 0 | AW17: 0 | AX17: 0 | AY17: 0 | AZ17: 0 | BA17: 0 | BB17: 0 | BC17: 0 | BD17: 0 | BE17: 0 | BF17: 0 | BG17: 0 | BH17: 0 | BI17: 0 | BJ17: 0 | BK17: 0 | BL17: 0 | BM17: 0 | BN17: 0 | BO17: 0 | BP17: 0 | BQ17: 0 | BR17: 0 | BS17: 0 | BT17: 0 | BU17: 0 | BV17: 0 | BW17: 0 | BX17: 0 | BY17: 0 | BZ17: 0 | CA17: 0 | CB17: 0 | CC17: 0 | CD17: 0 | CE17: 0 | CF17: 0 | CG17: 0 | CH17: 0 | CI17: 0 | CJ17: 0 | CK17: 0 | CL17: 0 | CM17: 0 | CN17: 0 | CO17: 0 | CP17: 0 | CQ17: 0 | CR17: 0 | CS17: 0 | CT17: 0 | CU17: 0 | CV17: 0 | CW17: 0 | CX17: 0 | CY17: 0 | CZ17: 0 | DA17: 0 | DB17: 0 | DC17: 0 | DD17: 0 | DE17: 0 | DF17: 0 | DG17: 0 | DH17: 0 | DI17: 0 | DJ17: 0 | DK17: 0 | DL17: 0 | DM17: 0 | DN17: 0 | DO17: 0 | DP17: 0 | DQ17: 0 | DR17: 0 | DS17: 0 | DT17: 0 | DU17: 0 | DV17: 0 | DW17: 0 | DX17: 0 | DY17: 0 | DZ17: 0 | EA17: 0
A18: =VLOOKUP(E18,'Validation List'!F19:G414,2,FALSE) -> January | B18: =INDEX('NEW HIRE ROSTER'!$G:$G,MATCH(RAW!F18,'NEW HIRE ROSTER'!$A:$A,0)) -> Nesting | C18: =INDEX('NEW HIRE ROSTER'!$F:$F,MATCH(RAW!F18,'NEW HIRE ROSTER'!$A:$A,0)) -> Class 11.2 | D18: =INDEX('Validation List'!$H:$H,MATCH(RAW!E18,'Validation List'!$F:$F,0)) -> Jan Week 1 | E18: 45667 | F18: Relano,Abimael Soliman | G18: =VLOOKUP(F18,ML!C18:D604,2,FALSE) -> Khyno Elimanco Cortez | H18: =VLOOKUP(F18,ML!C20:E606,3,FALSE) -> QC | I18: Gatchalian,Ernie Marie Caburian | J18: Provider | K18: "Status Check-Denied" | L18: INQ-F000964 | M18: 0.94 | N18: 0 | O18: 0 | P18: 0 | Q18: 0 | R18: 0 | S18: 0 | T18: 0 | U18: 0 | V18: 0 | W18: 0 | X18: 1 | Y18: 0 | Z18: 0 | AA18: 0 | AB18: 0 | AC18: 0 | AD18: 0 | AE18: 0 | AF18: 0 | AG18: 0 | AH18: 0 | AI18: 0 | AJ18: 0 | AK18: 0 | AL18: 0 | AM18: 0 | AN18: 0 | AO18: 0 | AP18: 0 | AQ18: 0 | AR18: 0 | AS18: 0 | AT18: 0 | AU18: 0 | AV18: 0 | AW18: 0 | AX18: 0 | AY18: 0 | AZ18: 0 | BA18: 0 | BB18: 0 | BC18: 0 | BD18: 0 | BE18: 0 | BF18: 0 | BG18: 0 | BH18: 0 | BI18: 0 | BJ18: 0 | BK18: 0 | BL18: 0 | BM18: 0 | BN18: 0 | BO18: 0 | BP18: 0 | BQ18: 0 | BR18: 0 | BS18: 0 | BT18: 0 | BU18: 0 | BV18: 0 | BW18: 0 | BX18: 0 | BY18: 0 | BZ18: 0 | CA18: 0 | CB18: 0 | CC18: 0 | CD18: 0 | CE18: 0 | CF18: 0 | CG18: 0 | CH18: 0 | CI18: 0 | CJ18: 0 | CK18: 0 | CL18: 0 | CM18: 0 | CN18: 0 | CO18: 0 | CP18: 0 | CQ18: 0 | CR18: 0 | CS18: 0 | CT18: 0 | CU18: 0 | CV18: 0 | CW18: 0 | CX18: 0 | CY18: 0 | CZ18: 0 | DA18: 0 | DB18: 0 | DC18: 0 | DD18: 0 | DE18: 0 | DF18: 0 | DG18: 0 | DH18: 0 | DI18: 0 | DJ18: 0 | DK18: 0 | DL18: 0 | DM18: 0 | DN18: 0 | DO18: 0 | DP18: 0 | DQ18: 0 | DR18: 0 | DS18: 0 | DT18: 0 | DU18: 0 | DV18: 0 | DW18: 0 | DX18: 0 | DY18: 0 | DZ18: 0 | EA18: 0
A19: =VLOOKUP(E19,'Validation List'!F20:G415,2,FALSE) -> January | B19: =INDEX('NEW HIRE ROSTER'!$G:$G,MATCH(RAW!F19,'NEW HIRE ROSTER'!$A:$A,0)) -> Nesting | C19: =INDEX('NEW HIRE ROSTER'!$F:$F,MATCH(RAW!F19,'NEW HIRE ROSTER'!$A:$A,0)) -> Class 11.2 | D19: =INDEX('Validation List'!$H:$H,MATCH(RAW!E19,'Validation List'!$F:$F,0)) -> Jan Week 1 | E19: 45666 | F19: Alzaga,Abigael Alano | G19: =VLOOKUP(F19,ML!C19:D605,2,FALSE) -> Khyno Elimanco Cortez | H19: =VLOOKUP(F19,ML!C21:E607,3,FALSE) -> QC | I19: Logmao,Nyrene Grace Lozada | J19: Provider | K19: "Call - Related to PA" | L19: INQ-E971669 | M19: 1 | N19: 0 | O19: 0 | P19: 0 | Q19: 0 | R19: 0 | S19: 0 | T19: 0 | U19: 0 | V19: 0 | W19: 0 | X19: 0 | Y19: 0 | Z19: 0 | AA19: 0 | AB19: 0 | AC19: 0 | AD19: 0 | AE19: 0 | AF19: 0 | AG19: 0 | AH19: 0 | AI19: 0 | AJ19: 0 | AK19: 0 | AL19: 0 | AM19: 0 | AN19: 0 | AO19: 0 | AP19: 0 | AQ19: 0 | AR19: 0 | AS19: 0 | AT19: 0 | AU19: 0 | AV19: 0 | AW19: 0 | AX19: 0 | AY19: 0 | AZ19: 0 | BA19: 0 | BB19: 0 | BC19: 0 | BD19: 0 | BE19: 0 | BF19: 0 | BG19: 0 | BH19: 0 | BI19: 0 | BJ19: 0 | BK19: 0 | BL19: 0 | BM19: 0 | BN19: 0 | BO19: 0 | BP19: 0 | BQ19: 0 | BR19: 0 | BS19: 0 | BT19: 0 | BU19: 0 | BV19: 0 | BW19: 0 | BX19: 0 | BY19: 0 | BZ19: 0 | CA19: 0 | CB19: 0 | CC19: 0 | CD19: 0 | CE19: 0 | CF19: 0 | CG19: 0 | CH19: 0 | CI19: 0 | CJ19: 0 | CK19: 0 | CL19: 0 | CM19: 0 | CN19: 0 | CO19: 0 | CP19: 0 | CQ19: 0 | CR19: 0 | CS19: 0 | CT19: 0 | CU19: 0 | CV19: 0 | CW19: 0 | CX19: 0 | CY19: 0 | CZ19: 0 | DA19: 0 | DB19: 0 | DC19: 0 | DD19: 0 | DE19: 0 | DF19: 0 | DG19: 0 | DH19: 0 | DI19: 0 | DJ19: 0 | DK19: 0 | DL19: 0 | DM19: 0 | DN19: 0 | DO19: 0 | DP19: 0 | DQ19: 0 | DR19: 0 | DS19: 0 | DT19: 0 | DU19: 0 | DV19: 0 | DW19: 0 | DX19: 0 | DY19: 0 | DZ19: 0 | EA19: 0
A20: =VLOOKUP(E20,'Validation List'!F21:G416,2,FALSE) -> January | B20: =INDEX('NEW HIRE ROSTER'!$G:$G,MATCH(RAW!F20,'NEW HIRE ROSTER'!$A:$A,0)) -> Nesting | C20: =INDEX('NEW HIRE ROSTER'!$F:$F,MATCH(RAW!F20,'NEW HIRE ROSTER'!$A:$A,0)) -> Class 11.1 | D20: =INDEX('Validation List'!$H:$H,MATCH(RAW!E20,'Validation List'!$F:$F,0)) -> Jan Week 1 | E20: 45667 | F20: Bonifacio,Melanie Gadia | G20: =VLOOKUP(F20,ML!C20:D606,2,FALSE) -> Robin Antolihao Llamido | H20: =VLOOKUP(F20,ML!C22:E608,3,FALSE) -> QC | I20: Logmao,Nyrene Grace Lozada | J20: Provider | K20: "Status Check-Approved" | L20: INQ-E996407 | M20: 0.94 | N20: 0 | O20: 0 | P20: 0 | Q20: 0 | R20: 0 | S20: 0 | T20: 0 | U20: 0 | V20: 0 | W20: 0 | X20: 1 | Y20: 0 | Z20: 0 | AA20: 0 | AB20: 0 | AC20: 0 | AD20: 0 | AE20: 0 | AF20: 0 | AG20: 0 | AH20: 0 | AI20: 0 | AJ20: 0 | AK20: 0 | AL20: 0 | AM20: 0 | AN20: 0 | AO20: 0 | AP20: 0 | AQ20: 0 | AR20: 0 | AS20: 0 | AT20: 0 | AU20: 0 | AV20: 0 | AW20: 0 | AX20: 0 | AY20: 0 | AZ20: 0 | BA20: 0 | BB20: 0 | BC20: 0 | BD20: 0 | BE20: 0 | BF20: 0 | BG20: 0 | BH20: 0 | BI20: 0 | BJ20: 0 | BK20: 0 | BL20: 0 | BM20: 0 | BN20: 0 | BO20: 0 | BP20: 0 | BQ20: 0 | BR20: 0 | BS20: 0 | BT20: 0 | BU20: 0 | BV20: 0 | BW20: 0 | BX20: 0 | BY20: 0 | BZ20: 0 | CA20: 0 | CB20: 0 | CC20: 0 | CD20: 0 | CE20: 0 | CF20: 0 | CG20: 0 | CH20: 0 | CI20: 0 | CJ20: 0 | CK20: 0 | CL20: 0 | CM20: 0 | CN20: 0 | CO20: 0 | CP20: 0 | CQ20: 0 | CR20: 0 | CS20: 0 | CT20: 0 | CU20: 0 | CV20: 0 | CW20: 0 | CX20: 0 | CY20: 0 | CZ20: 0 | DA20: 0 | DB20: 0 | DC20: 0 | DD20: 0 | DE20: 0 | DF20: 0 | DG20: 0 | DH20: 0 | DI20: 0 | DJ20: 0 | DK20: 0 | DL20: 0 | DM20: 0 | DN20: 0 | DO20: 0 | DP20: 0 | DQ20: 0 | DR20: 0 | DS20: 0 | DT20: 0 | DU20: 0 | DV20: 0 | DW20: 0 | DX20: 0 | DY20: 0 | DZ20: 0 | EA20: 0
A21: =VLOOKUP(E21,'Validation List'!F22:G417,2,FALSE) -> January | B21: =INDEX('NEW HIRE ROSTER'!$G:$G,MATCH(RAW!F21,'NEW HIRE ROSTER'!$A:$A,0)) -> Nesting | C21: =INDEX('NEW HIRE ROSTER'!$F:$F,MATCH(RAW!F21,'NEW HIRE ROSTER'!$A:$A,0)) -> Class 11.1 | D21: =INDEX('Validation List'!$H:$H,MATCH(RAW!E21,'Validation List'!$F:$F,0)) -> Jan Week 1 | E21: 45667 | F21: Austria,Effie Galang | G21: =VLOOKUP(F21,ML!C21:D607,2,FALSE) -> Robin Antolihao Llamido | H21: =VLOOKUP(F21,ML!C23:E609,3,FALSE) -> QC | I21: Logmao,Nyrene Grace Lozada | J21: Provider | K21: "Call - Related to PA" | L21: PA-E2308486 | M21: 0.94 | N21: 0 | O21: 0 | P21: 0 | Q21: 0 | R21: 0 | S21: 0 | T21: 0 | U21: 0 | V21: 0 | W21: 0 | X21: 1 | Y21: 0 | Z21: 0 | AA21: 0 | AB21: 0 | AC21: 0 | AD21: 0 | AE21: 0 | AF21: 0 | AG21: 0 | AH21: 0 | AI21: 0 | AJ21: 0 | AK21: 0 | AL21: 0 | AM21: 0 | AN21: 0 | AO21: 0 | AP21: 0 | AQ21: 0 | AR21: 0 | AS21: 0 | AT21: 0 | AU21: 0 | AV21: 0 | AW21: 0 | AX21: 0 | AY21: 0 | AZ21: 0 | BA21: 0 | BB21: 0 | BC21: 0 | BD21: 0 | BE21: 0 | BF21: 0 | BG21: 0 | BH21: 0 | BI21: 0 | BJ21: 0 | BK21: 0 | BL21: 0 | BM21: 0 | BN21: 0 | BO21: 0 | BP21: 0 | BQ21: 0 | BR21: 0 | BS21: 0 | BT21: 0 | BU21: 0 | BV21: 0 | BW21: 0 | BX21: 0 | BY21: 0 | BZ21: 0 | CA21: 0 | CB21: 0 | CC21: 0 | CD21: 0 | CE21: 0 | CF21: 0 | CG21: 0 | CH21: 0 | CI21: 0 | CJ21: 0 | CK21: 0 | CL21: 0 | CM21: 0 | CN21: 0 | CO21: 0 | CP21: 0 | CQ21: 0 | CR21: 0 | CS21: 0 | CT21: 0 | CU21: 0 | CV21: 0 | CW21: 0 | CX21: 0 | CY21: 0 | CZ21: 0 | DA21: 0 | DB21: 0 | DC21: 0 | DD21: 0 | DE21: 0 | DF21: 0 | DG21: 0 | DH21: 0 | DI21: 0 | DJ21: 0 | DK21: 0 | DL21: 0 | DM21: 0 | DN21: 0 | DO21: 0 | DP21: 0 | DQ21: 0 | DR21: 0 | DS21: 0 | DT21: 0 | DU21: 0 | DV21: 0 | DW21: 0 | DX21: 0 | DY21: 0 | DZ21: 0 | EA21: 0
A22: =VLOOKUP(E22,'Validation List'!F23:G418,2,FALSE) -> January | B22: =INDEX('NEW HIRE ROSTER'!$G:$G,MATCH(RAW!F22,'NEW HIRE ROSTER'!$A:$A,0)) -> Nesting | C22: =INDEX('NEW HIRE ROSTER'!$F:$F,MATCH(RAW!F22,'NEW HIRE ROSTER'!$A:$A,0)) -> Class 11.2 | D22: =INDEX('Validation List'!$H:$H,MATCH(RAW!E22,'Validation List'!$F:$F,0)) -> Jan Week 1 | E22: 45666 | F22: Ramos,Ruth Marionne Dalut | G22: =VLOOKUP(F22,ML!C22:D608,2,FALSE) -> Khyno Elimanco Cortez | H22: =VLOOKUP(F22,ML!C24:E610,3,FALSE) -> QC | I22: Napay,Rowena Joice Baguios | J22: Provider | K22: "Call - Related to PA" | L22: INQ-E964501 | M22: 0.99 | N22: 0 | O22: 0 | P22: 0 | Q22: 0 | R22: 0 | S22: 0 | T22: 0 | U22: 0 | V22: 0 | W22: 0 | X22: 0 | Y22: 0 | Z22: 0 | AA22: 0 | AB22: 0 | AC22: 0 | AD22: 0 | AE22: 0 | AF22: 0 | AG22: 0 | AH22: 0 | AI22: 0 | AJ22: 0 | AK22: 0 | AL22: 0 | AM22: 0 | AN22: 0 | AO22: 0 | AP22: 0 | AQ22: 0 | AR22: 0 | AS22: 0 | AT22: 0 | AU22: 0 | AV22: 0 | AW22: 0 | AX22: 0 | AY22: 0 | AZ22: 0 | BA22: 0 | BB22: 0 | BC22: 0 | BD22: 0 | BE22: 0 | BF22: 0 | BG22: 0 | BH22: 0 | BI22: 0 | BJ22: 0 | BK22: 0 | BL22: 0 | BM22: 0 | BN22: 0 | BO22: 0 | BP22: 0 | BQ22: 0 | BR22: 0 | BS22: 0 | BT22: 0 | BU22: 0 | BV22: 0 | BW22: 0 | BX22: 0 | BY22: 0 | BZ22: 0 | CA22: 0 | CB22: 0 | CC22: 0 | CD22: 0 | CE22: 0 | CF22: 0 | CG22: 0 | CH22: 0 | CI22: 0 | CJ22: 0 | CK22: 0 | CL22: 0 | CM22: 0 | CN22: 0 | CO22: 0 | CP22: 0 | CQ22: 0 | CR22: 0 | CS22: 0 | CT22: 0 | CU22: 1 | CV22: 0 | CW22: 0 | CX22: 0 | CY22: 0 | CZ22: 0 | DA22: 0 | DB22: 0 | DC22: 0 | DD22: 0 | DE22: 0 | DF22: 0 | DG22: 0 | DH22: 0 | DI22: 0 | DJ22: 0 | DK22: 0 | DL22: 0 | DM22: 0 | DN22: 0 | DO22: 0 | DP22: 0 | DQ22: 0 | DR22: 0 | DS22: 0 | DT22: 0 | DU22: 0 | DV22: 0 | DW22: 0 | DX22: 0 | DY22: 0 | DZ22: 0 | EA22: 0
A23: =VLOOKUP(E23,'Validation List'!F24:G419,2,FALSE) -> January | B23: =INDEX('NEW HIRE ROSTER'!$G:$G,MATCH(RAW!F23,'NEW HIRE ROSTER'!$A:$A,0)) -> Nesting | C23: =INDEX('NEW HIRE ROSTER'!$F:$F,MATCH(RAW!F23,'NEW HIRE ROSTER'!$A:$A,0)) -> Class 11.2 | D23: =INDEX('Validation List'!$H:$H,MATCH(RAW!E23,'Validation List'!$F:$F,0)) -> Jan Week 1 | E23: 45666 | F23: Ramos,Ruth Marionne Dalut | G23: =VLOOKUP(F23,ML!C23:D609,2,FALSE) -> Khyno Elimanco Cortez | H23: =VLOOKUP(F23,ML!C25:E611,3,FALSE) -> QC | I23: Napay,Rowena Joice Baguios | J23: Provider | K23: "Status Check-Approved" | L23: INQ-E965084 | M23: 0.99 | N23: 0 | O23: 0 | P23: 0 | Q23: 0 | R23: 0 | S23: 0 | T23: 0 | U23: 0 | V23: 0 | W23: 0 | X23: 0 | Y23: 0 | Z23: 0 | AA23: 0 | AB23: 0 | AC23: 0 | AD23: 0 | AE23: 0 | AF23: 0 | AG23: 0 | AH23: 0 | AI23: 0 | AJ23: 0 | AK23: 0 | AL23: 0 | AM23: 0 | AN23: 0 | AO23: 0 | AP23: 0 | AQ23: 0 | AR23: 0 | AS23: 0 | AT23: 0 | AU23: 0 | AV23: 0 | AW23: 0 | AX23: 0 | AY23: 0 | AZ23: 0 | BA23: 0 | BB23: 0 | BC23: 0 | BD23: 0 | BE23: 0 | BF23: 0 | BG23: 0 | BH23: 0 | BI23: 0 | BJ23: 0 | BK23: 0 | BL23: 0 | BM23: 0 | BN23: 0 | BO23: 0 | BP23: 0 | BQ23: 0 | BR23: 0 | BS23: 0 | BT23: 0 | BU23: 0 | BV23: 0 | BW23: 0 | BX23: 0 | BY23: 0 | BZ23: 0 | CA23: 0 | CB23: 0 | CC23: 0 | CD23: 0 | CE23: 0 | CF23: 0 | CG23: 0 | CH23: 0 | CI23: 0 | CJ23: 0 | CK23: 0 | CL23: 0 | CM23: 0 | CN23: 0 | CO23: 0 | CP23: 0 | CQ23: 0 | CR23: 0 | CS23: 0 | CT23: 0 | CU23: 1 | CV23: 0 | CW23: 0 | CX23: 0 | CY23: 0 | CZ23: 0 | DA23: 0 | DB23: 0 | DC23: 0 | DD23: 0 | DE23: 0 | DF23: 0 | DG23: 0 | DH23: 0 | DI23: 0 | DJ23: 0 | DK23: 0 | DL23: 0 | DM23: 0 | DN23: 0 | DO23: 0 | DP23: 0 | DQ23: 0 | DR23: 0 | DS23: 0 | DT23: 0 | DU23: 0 | DV23: 0 | DW23: 0 | DX23: 0 | DY23: 0 | DZ23: 0 | EA23: 0
... A37: =VLOOKUP(E37,'Validation List'!F38:G433,2,FALSE) -> January | B37: =INDEX('NEW HIRE ROSTER'!$G:$G,MATCH(RAW!F37,'NEW HIRE ROSTER'!$A:$A,0)) -> RAMP | C37: =INDEX('NEW HIRE ROSTER'!$F:$F,MATCH(RAW!F37,'NEW HIRE ROSTER'!$A:$A,0)) -> Class 10 | D37: =INDEX('Validation List'!$H:$H,MATCH(RAW!E37,'Validation List'!$F:$F,0)) -> Jan Week 2 | E37: 45670 | F37: Cubillas,Chenne Biazon | G37: =VLOOKUP(F37,ML!C37:D623,2,FALSE) -> Jeric Amazona Mansibang | H37: =VLOOKUP(F37,ML!C39:E625,3,FALSE) -> QC | I37: Santos,Jennilyn Chan | J37: Provider | K37: "Call Transferred" | L37: INQ-F027089 | M37: 1 | N37: 0 | O37: 0 | P37: 0 | Q37: 0 | R37: 0 | S37: 0 | T37: 0 | U37: 0 | V37: 0 | W37: 0 | X37: 0 | Y37: 0 | Z37: 0 | AA37: 0 | AB37: 0 | AC37: 0 | AD37: 0 | AE37: 0 | AF37: 0 | AG37: 0 | AH37: 0 | AI37: 0 | AJ37: 0 | AK37: 0 | AL37: 0 | AM37: 0 | AN37: 0 | AO37: 0 | AP37: 0 | AQ37: 0 | AR37: 0 | AS37: 0 | AT37: 0 | AU37: 0 | AV37: 0 | AW37: 0 | AX37: 0 | AY37: 0 | AZ37: 0 | BA37: 0 | BB37: 0 | BC37: 0 | BD37: 0 | BE37: 0 | BF37: 0 | BG37: 0 | BH37: 0 | BI37: 0 | BJ37: 0 | BK37: 0 | BL37: 0 | BM37: 0 | BN37: 0 | BO37: 0 | BP37: 0 | BQ37: 0 | BR37: 0 | BS37: 0 | BT37: 0 | BU37: 0 | BV37: 0 | BW37: 0 | BX37: 0 | BY37: 0 | BZ37: 0 | CA37: 0 | CB37: 0 | CC37: 0 | CD37: 0 | CE37: 0 | CF37: 0 | CG37: 0 | CH37: 0 | CI37: 0 | CJ37: 0 | CK37: 0 | CL37: 0 | CM37: 0 | CN37: 0 | CO37: 0 | CP37: 0 | CQ37: 0 | CR37: 0 | CS37: 0 | CT37: 0 | CU37: 0 | CV37: 0 | CW37: 0 | CX37: 0 | CY37: 0 | CZ37: 0 | DA37: 0 | DB37: 0 | DC37: 0 | DD37: 0 | DE37: 0 | DF37: 0 | DG37: 0 | DH37: 0 | DI37: 0 | DJ37: 0 | DK37: 0 | DL37: 0 | DM37: 0 | DN37: 0 | DO37: 0 | DP37: 0 | DQ37: 0 | DR37: 0 | DS37: 0 | DT37: 0 | DU37: 0 | DV37: 0 | DW37: 0 | DX37: 0 | DY37: 0 | DZ37: 0 | EA37: 0
A38: =VLOOKUP(E38,'Validation List'!F39:G434,2,FALSE) -> January | B38: =INDEX('NEW HIRE ROSTER'!$G:$G,MATCH(RAW!F38,'NEW HIRE ROSTER'!$A:$A,0)) -> RAMP | C38: =INDEX('NEW HIRE ROSTER'!$F:$F,MATCH(RAW!F38,'NEW HIRE ROSTER'!$A:$A,0)) -> Class 10 | D38: =INDEX('Validation List'!$H:$H,MATCH(RAW!E38,'Validation List'!$F:$F,0)) -> Jan Week 2 | E38: 45670 | F38: Bihag,Floriebel Dellona | G38: =VLOOKUP(F38,ML!C2:D600,2,FALSE) -> Jeric Amazona Mansibang | H38: =VLOOKUP(F38,ML!C2:E600,3,FALSE) -> QC | I38: Santos,Jennilyn Chan | J38: Provider | K38: New PA Initiation | L38: PA-E2425554 | M38: 1 | N38: 0 | O38: 0 | P38: 0 | Q38: 0 | R38: 0 | S38: 0 | T38: 0 | U38: 0 | V38: 0 | W38: 0 | X38: 0 | Y38: 0 | Z38: 0 | AA38: 0 | AB38: 0 | AC38: 0 | AD38: 0 | AE38: 0 | AF38: 0 | AG38: 0 | AH38: 0 | AI38: 0 | AJ38: 0 | AK38: 0 | AL38: 0 | AM38: 0 | AN38: 0 | AO38: 0 | AP38: 0 | AQ38: 0 | AR38: 0 | AS38: 0 | AT38: 0 | AU38: 0 | AV38: 0 | AW38: 0 | AX38: 0 | AY38: 0 | AZ38: 0 | BA38: 0 | BB38: 0 | BC38: 0 | BD38: 0 | BE38: 0 | BF38: 0 | BG38: 0 | BH38: 0 | BI38: 0 | BJ38: 0 | BK38: 0 | BL38: 0 | BM38: 0 | BN38: 0 | BO38: 0 | BP38: 0 | BQ38: 0 | BR38: 0 | BS38: 0 | BT38: 0 | BU38: 0 | BV38: 0 | BW38: 0 | BX38: 0 | BY38: 0 | BZ38: 0 | CA38: 0 | CB38: 0 | CC38: 0 | CD38: 0 | CE38: 0 | CF38: 0 | CG38: 0 | CH38: 0 | CI38: 0 | CJ38: 0 | CK38: 0 | CL38: 0 | CM38: 0 | CN38: 0 | CO38: 0 | CP38: 0 | CQ38: 0 | CR38: 0 | CS38: 0 | CT38: 0 | CU38: 0 | CV38: 0 | CW38: 0 | CX38: 0 | CY38: 0 | CZ38: 0 | DA38: 0 | DB38: 0 | DC38: 0 | DD38: 0 | DE38: 0 | DF38: 0 | DG38: 0 | DH38: 0 | DI38: 0 | DJ38: 0 | DK38: 0 | DL38: 0 | DM38: 0 | DN38: 0 | DO38: 0 | DP38: 0 | DQ38: 0 | DR38: 0 | DS38: 0 | DT38: 0 | DU38: 0 | DV38: 0 | DW38: 0 | DX38: 0 | DY38: 0 | DZ38: 0 | EA38: 0
A39: =VLOOKUP(E39,'Validation List'!F40:G435,2,FALSE) -> January | B39: =INDEX('NEW HIRE ROSTER'!$G:$G,MATCH(RAW!F39,'NEW HIRE ROSTER'!$A:$A,0)) -> RAMP | C39: =INDEX('NEW HIRE ROSTER'!$F:$F,MATCH(RAW!F39,'NEW HIRE ROSTER'!$A:$A,0)) -> Class 10 | D39: =INDEX('Validation List'!$H:$H,MATCH(RAW!E39,'Validation List'!$F:$F,0)) -> Jan Week 2 | E39: 45670 | F39: Bihag,Floriebel Dellona | G39: =VLOOKUP(F39,ML!C3:D601,2,FALSE) -> Jeric Amazona Mansibang | H39: =VLOOKUP(F39,ML!C3:E601,3,FALSE) -> QC | I39: Santos,Jennilyn Chan | J39: Provider | K39: New PA Initiation | L39: PA-E2423570 | M39: 1 | N39: 0 | O39: 0 | P39: 0 | Q39: 0 | R39: 0 | S39: 0 | T39: 0 | U39: 0 | V39: 0 | W39: 0 | X39: 0 | Y39: 0 | Z39: 0 | AA39: 0 | AB39: 0 | AC39: 0 | AD39: 0 | AE39: 0 | AF39: 0 | AG39: 0 | AH39: 0 | AI39: 0 | AJ39: 0 | AK39: 0 | AL39: 0 | AM39: 0 | AN39: 0 | AO39: 0 | AP39: 0 | AQ39: 0 | AR39: 0 | AS39: 0 | AT39: 0 | AU39: 0 | AV39: 0 | AW39: 0 | AX39: 0 | AY39: 0 | AZ39: 0 | BA39: 0 | BB39: 0 | BC39: 0 | BD39: 0 | BE39: 0 | BF39: 0 | BG39: 0 | BH39: 0 | BI39: 0 | BJ39: 0 | BK39: 0 | BL39: 0 | BM39: 0 | BN39: 0 | BO39: 0 | BP39: 0 | BQ39: 0 | BR39: 0 | BS39: 0 | BT39: 0 | BU39: 0 | BV39: 0 | BW39: 0 | BX39: 0 | BY39: 0 | BZ39: 0 | CA39: 0 | CB39: 0 | CC39: 0 | CD39: 0 | CE39: 0 | CF39: 0 | CG39: 0 | CH39: 0 | CI39: 0 | CJ39: 0 | CK39: 0 | CL39: 0 | CM39: 0 | CN39: 0 | CO39: 0 | CP39: 0 | CQ39: 0 | CR39: 0 | CS39: 0 | CT39: 0 | CU39: 0 | CV39: 0 | CW39: 0 | CX39: 0 | CY39: 0 | CZ39: 0 | DA39: 0 | DB39: 0 | DC39: 0 | DD39: 0 | DE39: 0 | DF39: 0 | DG39: 0 | DH39: 0 | DI39: 0 | DJ39: 0 | DK39: 0 | DL39: 0 | DM39: 0 | DN39: 0 | DO39: 0 | DP39: 0 | DQ39: 0 | DR39: 0 | DS39: 0 | DT39: 0 | DU39: 0 | DV39: 0 | DW39: 0 | DX39: 0 | DY39: 0 | DZ39: 0 | EA39: 0
